<?xml version="1.0" encoding="utf-8"?>
<!-- This URDF was automatically created by SolidWorks to URDF Exporter! Originally created by Stephen Brawner (brawner@gmail.com) 
     Commit Version: 1.6.0-4-g7f85cfe  Build Version: 1.6.7995.38578
     For more information, please see http://wiki.ros.org/sw_urdf_exporter -->
<robot
  name="ydpibot_description">
  <link
    name="base_link">
    <inertial>
      <origin
        xyz="-0.0093884 -8.3267E-17 0.047189"
        rpy="0 0 0" />
      <mass
        value="0.11353" />
      <inertia
        ixx="0"
        ixy="0"
        ixz="0"
        iyy="0"
        iyz="0"
        izz="0" />
    </inertial>
    <visual>
      <origin
        xyz="0 0 0"
        rpy="0 0 0" />
      <geometry>
        <mesh
          filename="package://ydpibot_description/meshes/base_link.STL" />
      </geometry>
      <material
        name="">
        <color
          rgba="1 0 0 1" />
      </material>
    </visual>
    <collision>
      <origin
        xyz="0 0 0"
        rpy="0 0 0" />
      <geometry>
        <mesh
          filename="package://ydpibot_description/meshes/base_link.STL" />
      </geometry>
    </collision>
  </link>
  <link
    name="Upper_base">
    <inertial>
      <origin
        xyz="-0.00023228 -5.5511E-17 0.0015"
        rpy="0 0 0" />
      <mass
        value="0.072243" />
      <inertia
        ixx="7.9419E-05"
        ixy="-2.5265E-19"
        ixz="1.9615E-20"
        iyy="0.00027821"
        iyz="3.6365E-21"
        izz="0.00035752" />
    </inertial>
    <visual>
      <origin
        xyz="0 0 0"
        rpy="0 0 0" />
      <geometry>
        <mesh
          filename="package://ydpibot_description/meshes/Upper_base.STL" />
      </geometry>
      <material
        name="">
        <color
          rgba="1 0 0 1" />
      </material>
    </visual>
    <collision>
      <origin
        xyz="0 0 0"
        rpy="0 0 0" />
      <geometry>
        <mesh
          filename="package://ydpibot_description/meshes/Upper_base.STL" />
      </geometry>
    </collision>
  </link>
  <joint
    name="Upper_base"
    type="fixed">
    <origin
      xyz="-0.0019675 0 0.0895"
      rpy="0 0 0" />
    <parent
      link="base_link" />
    <child
      link="Upper_base" />
    <axis
      xyz="0 0 0" />
  </joint>
  <link
    name="spacer1">
    <inertial>
      <origin
        xyz="-2.7756E-17 -9.7145E-17 -0.017"
        rpy="0 0 0" />
      <mass
        value="0.0038202" />
      <inertia
        ixx="7.5881E-07"
        ixy="-1.672E-24"
        ixz="3.7903E-23"
        iyy="7.5881E-07"
        iyz="4.1639E-23"
        izz="5.1484E-08" />
    </inertial>
    <visual>
      <origin
        xyz="0 0 0"
        rpy="0 0 0" />
      <geometry>
        <mesh
          filename="package://ydpibot_description/meshes/spacer1.STL" />
      </geometry>
      <material
        name="">
        <color
          rgba="0 1 0 1" />
      </material>
    </visual>
    <collision>
      <origin
        xyz="0 0 0"
        rpy="0 0 0" />
      <geometry>
        <mesh
          filename="package://ydpibot_description/meshes/spacer1.STL" />
      </geometry>
    </collision>
  </link>
  <joint
    name="spacer1_joint"
    type="continuous">
    <origin
      xyz="0.084615 0.055 0"
      rpy="0 0 0" />
    <parent
      link="Upper_base" />
    <child
      link="spacer1" />
    <axis
      xyz="0 0 1" />
  </joint>
  <link
    name="spacer2">
    <inertial>
      <origin
        xyz="-8.3267E-17 -8.3267E-17 -0.017"
        rpy="0 0 0" />
      <mass
        value="0.0038202" />
      <inertia
        ixx="7.5881E-07"
        ixy="-3.5E-24"
        ixz="3.2864E-21"
        iyy="7.5881E-07"
        iyz="3.2535E-23"
        izz="5.1484E-08" />
    </inertial>
    <visual>
      <origin
        xyz="0 0 0"
        rpy="0 0 0" />
      <geometry>
        <mesh
          filename="package://ydpibot_description/meshes/spacer2.STL" />
      </geometry>
      <material
        name="">
        <color
          rgba="0 1 0 1" />
      </material>
    </visual>
    <collision>
      <origin
        xyz="0 0 0"
        rpy="0 0 0" />
      <geometry>
        <mesh
          filename="package://ydpibot_description/meshes/spacer2.STL" />
      </geometry>
    </collision>
  </link>
  <joint
    name="spacer2_joint"
    type="continuous">
    <origin
      xyz="0.0846153846153847 -0.0549999999999999 0"
      rpy="0 0 0" />
    <parent
      link="Upper_base" />
    <child
      link="spacer2" />
    <axis
      xyz="0 0 1" />
  </joint>
  <link
    name="spacer3">
    <inertial>
      <origin
        xyz="-7.6328E-17 8.3267E-17 -0.017"
        rpy="0 0 0" />
      <mass
        value="0.0038202" />
      <inertia
        ixx="7.5881E-07"
        ixy="-9.9272E-25"
        ixz="3.3078E-21"
        iyy="7.5881E-07"
        iyz="1.6292E-26"
        izz="5.1484E-08" />
    </inertial>
    <visual>
      <origin
        xyz="0 0 0"
        rpy="0 0 0" />
      <geometry>
        <mesh
          filename="package://ydpibot_description/meshes/spacer3.STL" />
      </geometry>
      <material
        name="">
        <color
          rgba="0 1 0 1" />
      </material>
    </visual>
    <collision>
      <origin
        xyz="0 0 0"
        rpy="0 0 0" />
      <geometry>
        <mesh
          filename="package://ydpibot_description/meshes/spacer3.STL" />
      </geometry>
    </collision>
  </link>
  <joint
    name="spacer3_joiint"
    type="continuous">
    <origin
      xyz="-0.0846153846153847 -0.0549999999999999 0"
      rpy="0 0 0" />
    <parent
      link="Upper_base" />
    <child
      link="spacer3" />
    <axis
      xyz="0 0 1" />
  </joint>
  <link
    name="spacer4">
    <inertial>
      <origin
        xyz="-6.9389E-18 2.7756E-17 -0.017"
        rpy="0 0 0" />
      <mass
        value="0.0038202" />
      <inertia
        ixx="7.5881E-07"
        ixy="-1.1602E-24"
        ixz="3.3017E-21"
        iyy="7.5881E-07"
        iyz="3.9363E-23"
        izz="5.1484E-08" />
    </inertial>
    <visual>
      <origin
        xyz="0 0 0"
        rpy="0 0 0" />
      <geometry>
        <mesh
          filename="package://ydpibot_description/meshes/spacer4.STL" />
      </geometry>
      <material
        name="">
        <color
          rgba="0 1 0 1" />
      </material>
    </visual>
    <collision>
      <origin
        xyz="0 0 0"
        rpy="0 0 0" />
      <geometry>
        <mesh
          filename="package://ydpibot_description/meshes/spacer4.STL" />
      </geometry>
    </collision>
  </link>
  <joint
    name="spacer4_joint"
    type="continuous">
    <origin
      xyz="-0.0846153846153847 0.055 0"
      rpy="0 0 0" />
    <parent
      link="Upper_base" />
    <child
      link="spacer4" />
    <axis
      xyz="0 0 1" />
  </joint>
  <link
    name="base_scan">
    <inertial>
      <origin
        xyz="0.010012 8.6042E-16 -0.015783"
        rpy="0 0 0" />
      <mass
        value="0.032124" />
      <inertia
        ixx="6.0421E-06"
        ixy="-8.5949E-20"
        ixz="-2.1245E-19"
        iyy="1.7716E-05"
        iyz="3.464E-20"
        izz="2.1195E-05" />
    </inertial>
    <visual>
      <origin
        xyz="0 0 0"
        rpy="0 0 0" />
      <geometry>
        <mesh
          filename="package://ydpibot_description/meshes/base_scan.STL" />
      </geometry>
      <material
        name="">
        <color
          rgba="0 0 1 1" />
      </material>
    </visual>
    <collision>
      <origin
        xyz="0 0 0"
        rpy="0 0 0" />
      <geometry>
        <mesh
          filename="package://ydpibot_description/meshes/base_scan.STL" />
      </geometry>
    </collision>
  </link>
  <joint
    name="base_scan_joint"
    type="fixed">
    <origin
      xyz="-0.0397250065539057 0 0.049480432620002"
      rpy="0 0 0" />
    <parent
      link="Upper_base" />
    <child
      link="base_scan" />
    <axis
      xyz="0 0 0" />
  </joint>
  <link
    name="right_wheel">
    <inertial>
      <origin
        xyz="-4.5103E-16 -0.0125 5.0654E-16"
        rpy="0 0 0" />
      <mass
        value="0.075104" />
      <inertia
        ixx="2.5621E-05"
        ixy="-2.035E-39"
        ixz="-2.9995E-39"
        iyy="4.3419E-05"
        iyz="7.1293E-38"
        izz="2.5621E-05" />
    </inertial>
    <visual>
      <origin
        xyz="0 0 0"
        rpy="0 0 0" />
      <geometry>
        <mesh
          filename="package://ydpibot_description/meshes/right_wheel.STL" />
      </geometry>
      <material
        name="">
        <color
          rgba="1 1 0 1" />
      </material>
    </visual>
    <collision>
      <origin
        xyz="0 0 0"
        rpy="0 0 0" />
      <geometry>
        <mesh
          filename="package://ydpibot_description/meshes/right_wheel.STL" />
      </geometry>
    </collision>
  </link>
  <joint
    name="right_wheel_joint"
    type="continuous">
    <origin
      xyz="-0.021967 -0.055 0.0325"
      rpy="0 0 0" />
    <parent
      link="base_link" />
    <child
      link="right_wheel" />
    <axis
      xyz="0 1 0" />
  </joint>
    <transmission name="right_wheel_transmission">
    <type>transmission_interface/SimpleTransmission</type>
    <joint name="right_wheel_joint">
      <hardwareInterface>hardware_interface/VelocityJointInterface</hardwareInterface>  
    </joint>
    <actuator name="right_wheel_actuator">
      <mechanicalReduction>7</mechanicalReduction>
      <hardwareInterface>VelocityJointInterface</hardwareInterface>
    </actuator>
  </transmission>
  <link
    name="left_wheel">
    <inertial>
      <origin
        xyz="-4.7184E-16 -0.0125 4.7184E-16"
        rpy="0 0 0" />
      <mass
        value="0.075104" />
      <inertia
        ixx="2.5621E-05"
        ixy="-3.0526E-38"
        ixz="-2.9995E-39"
        iyy="4.3419E-05"
        iyz="7.1293E-38"
        izz="2.5621E-05" />
    </inertial>
    <visual>
      <origin
        xyz="0 0 0"
        rpy="0 0 0" />
      <geometry>
        <mesh
          filename="package://ydpibot_description/meshes/left_wheel.STL" />
      </geometry>
      <material
        name="">
        <color
          rgba="1 1 0 1" />
      </material>
    </visual>
    <collision>
      <origin
        xyz="0 0 0"
        rpy="0 0 0" />
      <geometry>
        <mesh
          filename="package://ydpibot_description/meshes/left_wheel.STL" />
      </geometry>
    </collision>
  </link>
  <joint
    name="left_wheel_joint"
    type="continuous">
    <origin
      xyz="-0.021967 0.08 0.0325"
      rpy="0 0 0" />
    <parent
      link="base_link" />
    <child
      link="left_wheel" />
    <axis
      xyz="0 1 0" />
  </joint>
    <transmission name="left_wheel_transmission">
    <type>transmission_interface/SimpleTransmission</type>
    <joint name="left_wheel_joint">
      <hardwareInterface>VelocityJointInterface</hardwareInterface>  
    </joint>
    <actuator name="left_wheel_actuator">
      <mechanicalReduction>7</mechanicalReduction>
      <hardwareInterface>VelocityJointInterface</hardwareInterface>
    </actuator>
  </transmission>
  <link
    name="caster_wheel_base">
    <inertial>
      <origin
        xyz="0 0 0"
        rpy="0 0 0" />
      <mass
        value="0" />
      <inertia
        ixx="0"
        ixy="0"
        ixz="0"
        iyy="0"
        iyz="0"
        izz="0" />
    </inertial>
    <visual>
      <origin
        xyz="0 0 0"
        rpy="0 0 0" />
      <geometry>
        <mesh
          filename="package://ydpibot_description/meshes/caster_wheel_base.STL" />
      </geometry>
      <material
        name="">
        <color
          rgba="1 1 1 1" />
      </material>
    </visual>
    <collision>
      <origin
        xyz="0 0 0"
        rpy="0 0 0" />
      <geometry>
        <mesh
          filename="package://ydpibot_description/meshes/caster_wheel_base.STL" />
      </geometry>
    </collision>
  </link>
  <joint
    name="caster_wheel_base_joint"
    type="fixed">
    <origin
      xyz="0.0550228988474612 -0.0125000000000001 0.0464999999999998"
      rpy="0 0 0" />
    <parent
      link="base_link" />
    <child
      link="caster_wheel_base" />
    <axis
      xyz="0 0 0" />
  </joint>
  <link
    name="caster_wheel_cage">
    <inertial>
      <origin
        xyz="0.021711 0.0078586 -0.0053453"
        rpy="0 0 0" />
      <mass
        value="0.056621" />
      <inertia
        ixx="7.5699E-06"
        ixy="1.2066E-07"
        ixz="7.9958E-07"
        iyy="8.0701E-06"
        iyz="-1.8276E-07"
        izz="1.077E-05" />
    </inertial>
    <visual>
      <origin
        xyz="0 0 0"
        rpy="0 0 0" />
      <geometry>
        <mesh
          filename="package://ydpibot_description/meshes/caster_wheel_cage.STL" />
      </geometry>
      <material
        name="">
        <color
          rgba="0 1 1 1" />
      </material>
    </visual>
    <collision>
      <origin
        xyz="0 0 0"
        rpy="0 0 0" />
      <geometry>
        <mesh
          filename="package://ydpibot_description/meshes/caster_wheel_cage.STL" />
      </geometry>
    </collision>
  </link>
  <joint
    name="caster_wheel_cage_joint"
    type="fixed">
    <origin
      xyz="-0.00235708009540958 0.00411504444057814 -0.00400000000000002"
      rpy="0 0 0" />
    <parent
      link="caster_wheel_base" />
    <child
      link="caster_wheel_cage" />
    <axis
      xyz="0 0 0" />
  </joint>
  <link
    name="caster_wheel">
    <inertial>
      <origin
        xyz="2.7756E-17 -2.7756E-17 3.4694E-18"
        rpy="0 0 0" />
      <mass
        value="0.017472" />
      <inertia
        ixx="2.3081E-06"
        ixy="2.9149E-07"
        ixz="-1.6066E-22"
        iyy="3.5164E-06"
        iyz="-9.113E-22"
        izz="2.2415E-06" />
    </inertial>
    <visual>
      <origin
        xyz="0 0 0"
        rpy="0 0 0" />
      <geometry>
        <mesh
          filename="package://ydpibot_description/meshes/caster_wheel.STL" />
      </geometry>
      <material
        name="">
        <color
          rgba="1 1 1 1" />
      </material>
    </visual>
    <collision>
      <origin
        xyz="0 0 0"
        rpy="0 0 0" />
      <geometry>
        <mesh
          filename="package://ydpibot_description/meshes/caster_wheel.STL" />
      </geometry>
    </collision>
  </link>
  <joint
    name="caster_wheel_joint"
    type="fixed">
    <origin
      xyz="0.0350067859440261 0.00481885237829768 -0.0229999999999999"
      rpy="0 0 0" />
    <parent
      link="caster_wheel_cage" />
    <child
      link="caster_wheel" />
    <axis
      xyz="0 0 0" />
  </joint>

  <gazebo>
    <plugin name="gazebo_ros_control" filename="libgazebo_ros_control.so">
      <robotNamespace>/</robotNamespace>
    </plugin>
  </gazebo>

</robot>