<?xml version="1.0" encoding="utf-8"?>
<!-- This URDF was automatically created by SolidWorks to URDF Exporter! Originally created by Stephen Brawner (brawner@gmail.com) 
     Commit Version: 1.6.0-4-g7f85cfe  Build Version: 1.6.7995.38578
     For more information, please see http://wiki.ros.org/sw_urdf_exporter -->
<robot
  name="ydpibot_description">
  <link
    name="base_link">
    <visual>
      <origin
        xyz="0 0 0"
        rpy="0 0 0" />
      <geometry>
        <mesh
          filename="package://ydpibot_description/meshes/base_link.STL" />
      </geometry>
      <material
        name="">
        <color
          rgba="0.79216 0.81961 0.93333 1" />
      </material>
    </visual>
    <collision>
      <origin
        xyz="0 0 0"
        rpy="0 0 0" />
      <geometry>
        <mesh
          filename="package://ydpibot_description/meshes/base_link.STL" />
      </geometry>
    </collision>
  </link>
  <gazebo reference="base_link">
    <mu1 value="1.0"/>
    <mu2 value="1.0"/>
    <kp value="10000000.0"/>
    <kd value="1.0"/>
    <fdir1 value="1 0 0"/>
    <material>Gazebo/Wood</material>
    <turnGravityOff>false</turnGravityOff>
  </gazebo>
  <link
    name="Upper_base">
    <inertial>
      <origin
        xyz="-0.00023228 0 0.0165"
        rpy="0 0 0" />
      <mass
        value="0.072243" />
      <inertia
        ixx="7.9419E-05"
        ixy="-2.2935E-19"
        ixz="7.6782E-21"
        iyy="0.00027821"
        iyz="3.7343E-21"
        izz="0.50035752" />
    </inertial>
    <visual>
      <origin
        xyz="0 0 0"
        rpy="0 0 0" />
      <geometry>
        <mesh
          filename="package://ydpibot_description/meshes/Upper_base.STL" />
      </geometry>
      <material
        name="">
        <color
          rgba="0.79216 0.81961 0.93333 1" />
      </material>
    </visual>
    <collision>
      <origin
        xyz="0 0 0"
        rpy="0 0 0" />
      <geometry>
        <mesh
          filename="package://ydpibot_description/meshes/Upper_base.STL" />
      </geometry>
    </collision>
  </link>
  <gazebo reference="Upper_base">
    <mu1 value="1.0"/>
    <mu2 value="1.0"/>
    <kp value="10000000.0"/>
    <kd value="1.0"/>
    <fdir1 value="1 0 0"/>
    <material>Gazebo/Wood</material>
    <turnGravityOff>false</turnGravityOff>
  </gazebo>
  <joint
    name="Upper_base"
    type="fixed">
    <origin
      xyz="-0.0019675 0 0.0895"
      rpy="0 0 0" />
    <parent
      link="base_link" />
    <child
      link="Upper_base" />
    <axis
      xyz="0 0 0" />
  </joint>
  <link
    name="spacer1">
    <inertial>
      <origin
        xyz="2.7756E-17 2.7756E-17 -0.0095"
        rpy="0 0 0" />
      <mass
        value="0.0049983" />
      <inertia
        ixx="1.6932E-06"
        ixy="1.5579E-24"
        ixz="6.0789E-23"
        iyy="1.6932E-06"
        iyz="3.0979E-22"
        izz="6.6211E-08" />
    </inertial>
    <visual>
      <origin
        xyz="0 0 0"
        rpy="0 0 0" />
      <geometry>
        <mesh
          filename="package://ydpibot_description/meshes/spacer1.STL" />
      </geometry>
      <material
        name="">
        <color
          rgba="1 1 0 1" />
      </material>
    </visual>
    <collision>
      <origin
        xyz="0 0 0"
        rpy="0 0 0" />
      <geometry>
        <mesh
          filename="package://ydpibot_description/meshes/spacer1.STL" />
      </geometry>
    </collision>
  </link>
  <gazebo reference="spacer1">
    <mu1 value="1.0"/>
    <mu2 value="1.0"/>
    <kp value="10000000.0"/>
    <kd value="1.0"/>
    <fdir1 value="1 0 0"/>
    <material>Gazebo/ZincYellow</material>
    <turnGravityOff>false</turnGravityOff>
  </gazebo>
  <joint
    name="spacer1_joint"
    type="fixed">
    <origin
      xyz="0.084615 0.055 0"
      rpy="0 0 0" />
    <parent
      link="Upper_base" />
    <child
      link="spacer1" />
    <axis
      xyz="0 0 0" />
  </joint>
  <link
    name="spacer2">
    <inertial>
      <origin
        xyz="4.1633E-16 -2.7756E-17 -0.0095"
        rpy="0 0 0" />
      <mass
        value="0.0049983" />
      <inertia
        ixx="1.6932E-06"
        ixy="2.1369E-25"
        ixz="7.5795E-21"
        iyy="1.6932E-06"
        iyz="8.4589E-23"
        izz="6.6211E-08" />
    </inertial>
    <visual>
      <origin
        xyz="0 0 0"
        rpy="0 0 0" />
      <geometry>
        <mesh
          filename="package://ydpibot_description/meshes/spacer2.STL" />
      </geometry>
      <material
        name="">
        <color
          rgba="1 1 0 1" />
      </material>
    </visual>
    <collision>
      <origin
        xyz="0 0 0"
        rpy="0 0 0" />
      <geometry>
        <mesh
          filename="package://ydpibot_description/meshes/spacer2.STL" />
      </geometry>
    </collision>
  </link>
  <gazebo reference="spacer2">
    <mu1 value="1.0"/>
    <mu2 value="1.0"/>
    <kp value="10000000.0"/>
    <kd value="1.0"/>
    <fdir1 value="1 0 0"/>
    <material>Gazebo/ZincYellow</material>
    <turnGravityOff>false</turnGravityOff>
  </gazebo>
  <joint
    name="spacer2_joint"
    type="fixed">
    <origin
      xyz="0.084615 -0.055 0"
      rpy="0 0 0" />
    <parent
      link="Upper_base" />
    <child
      link="spacer2" />
    <axis
      xyz="0 0 0" />
  </joint>
  <link
    name="spacer3">
    <inertial>
      <origin
        xyz="-1.5474E-15 2.7756E-17 -0.0095"
        rpy="0 0 0" />
      <mass
        value="0.0049983" />
      <inertia
        ixx="1.6932E-06"
        ixy="-1.1126E-25"
        ixz="7.5759E-21"
        iyy="1.6932E-06"
        iyz="8.7991E-24"
        izz="6.6211E-08" />
    </inertial>
    <visual>
      <origin
        xyz="0 0 0"
        rpy="0 0 0" />
      <geometry>
        <mesh
          filename="package://ydpibot_description/meshes/spacer3.STL" />
      </geometry>
      <material
        name="">
        <color
          rgba="1 1 0 1" />
      </material>
    </visual>
    <collision>
      <origin
        xyz="0 0 0"
        rpy="0 0 0" />
      <geometry>
        <mesh
          filename="package://ydpibot_description/meshes/spacer3.STL" />
      </geometry>
    </collision>
  </link>
  <gazebo reference="spacer3">
    <mu1 value="1.0"/>
    <mu2 value="1.0"/>
    <kp value="10000000.0"/>
    <kd value="1.0"/>
    <fdir1 value="1 0 0"/>
    <material>Gazebo/ZincYellow</material>
    <turnGravityOff>false</turnGravityOff>
  </gazebo>
  <joint
    name="spacer3_joiint"
    type="fixed">
    <origin
      xyz="-0.084615 -0.055 0"
      rpy="0 0 0" />
    <parent
      link="Upper_base" />
    <child
      link="spacer3" />
    <axis
      xyz="0 0 0" />
  </joint>
  <link
    name="spacer4">
    <inertial>
      <origin
        xyz="-1.5959E-15 1.3878E-17 -0.0095"
        rpy="0 0 0" />
      <mass
        value="0.0049983" />
      <inertia
        ixx="1.6932E-06"
        ixy="1.4885E-24"
        ixz="7.595E-21"
        iyy="1.6932E-06"
        iyz="8.3237E-23"
        izz="6.6211E-08" />
    </inertial>
    <visual>
      <origin
        xyz="0 0 0"
        rpy="0 0 0" />
      <geometry>
        <mesh
          filename="package://ydpibot_description/meshes/spacer4.STL" />
      </geometry>
      <material
        name="">
        <color
          rgba="1 1 0 1" />
      </material>
    </visual>
    <collision>
      <origin
        xyz="0 0 0"
        rpy="0 0 0" />
      <geometry>
        <mesh
          filename="package://ydpibot_description/meshes/spacer4.STL" />
      </geometry>
    </collision>
  </link>
  <gazebo reference="spacer4">
    <mu1 value="1.0"/>
    <mu2 value="1.0"/>
    <kp value="10000000.0"/>
    <kd value="1.0"/>
    <fdir1 value="1 0 0"/>
    <material>Gazebo/ZincYellow</material>
    <turnGravityOff>false</turnGravityOff>
  </gazebo>
  <joint
    name="spacer4_joint"
    type="fixed">
    <origin
      xyz="-0.084615 0.055 0"
      rpy="0 0 0" />
    <parent
      link="Upper_base" />
    <child
      link="spacer4" />
    <axis
      xyz="0 0 0" />
  </joint>
  <link
    name="base_scan">
    <inertial>
      <origin
        xyz="0.010012 8.3267E-17 -0.00078299"
        rpy="0 0 0" />
      <mass
        value="0.032124" />
      <inertia
        ixx="6.0421E-06"
        ixy="-8.5096E-20"
        ixz="-2.1525E-19"
        iyy="1.7716E-05"
        iyz="3.5491E-20"
        izz="2.1195E-05" />
    </inertial>
    <visual>
      <origin
        xyz="0 0 0"
        rpy="0 0 0" />
      <geometry>
        <mesh
          filename="package://ydpibot_description/meshes/base_scan.STL" />
      </geometry>
      <material
        name="">
        <color
          rgba="0 0 1 1" />
      </material>
    </visual>
    <collision>
      <origin
        xyz="0 0 0"
        rpy="0 0 0" />
      <geometry>
        <mesh
          filename="package://ydpibot_description/meshes/base_scan.STL" />
      </geometry>
    </collision>
  </link>
    <gazebo reference="base_scan">
        <material>Gazebo/Blue</material>

        <sensor name="laser" type="ray">
            <pose> 0 0 0 0 0 0 </pose>
            <visualize>false</visualize>
            <update_rate>10</update_rate>
            <ray>
                <scan>
                    <horizontal>
                        <samples>360</samples>
                        <min_angle>-3.14</min_angle>
                        <max_angle>3.14</max_angle>
                    </horizontal>
                </scan>
                <range>
                    <min>0.3</min>
                    <max>12</max>
                </range>
            </ray>
            <plugin name="laser_controller" filename="libgazebo_ros_laser.so">
                <topicName>scan</topicName>
                <output_type>sensor_msgs/LaserScan</output_type>
                <frame_name>base_scan</frame_name>
            </plugin>
        </sensor>
    </gazebo>
  <joint
    name="base_scan_joint"
    type="fixed">
    <origin
      xyz="-0.039725 0 0.04948"
      rpy="0 0 0" />
    <parent
      link="Upper_base" />
    <child
      link="base_scan" />
    <axis
      xyz="0 0 0" />
  </joint>
  <link
    name="right_wheel">
    <inertial>
      <origin
        xyz="-6.9389E-18 -0.0125 6.9389E-18"
        rpy="0 0 0" />
      <mass
        value="0.1" />
      <inertia
        ixx="2.5621E-05"
        ixy="-3.0526E-18"
        ixz="-2.9995E-19"
        iyy="8.3419E-03"
        iyz="7.1293E-18"
        izz="2.5621E-05" />
    </inertial>
    <visual>
      <origin
        xyz="0 0 0"
        rpy="0 0 0" />
      <geometry>
        <mesh
          filename="package://ydpibot_description/meshes/right_wheel.STL" />
      </geometry>
      <material
        name="">
        <color
          rgba="0 1 1 1" />
      </material>
    </visual>
    <collision>
      <origin
        xyz="0 0 0"
        rpy="0 0 0" />
      <geometry>
        <mesh
          filename="package://ydpibot_description/meshes/right_wheel.STL" />
      </geometry>
    </collision>
  </link>
  <gazebo reference="right_wheel">
    <mu1 value="1.0"/>
    <mu2 value="1.0"/>
    <kp value="10000000.0"/>
    <kd value="10.0"/>
    <fdir1 value="1 0 0"/>
    <material>Gazebo/Yellow</material>
    <turnGravityOff>false</turnGravityOff>
  </gazebo>
  <joint
    name="right_wheel_joint"
    type="continuous">
    <origin
      xyz="-0.021967 -0.055 0.0325"
      rpy="0 0 0" />
    <parent
      link="base_link" />
    <child
      link="right_wheel" />
    <axis
      xyz="0 1 0" />
  </joint>
  <transmission name="right_wheel_transmission">
    <type>transmission_interface/SimpleTransmission</type>
    <joint name="right_wheel_joint">
      <hardwareInterface>hardware_interface/VelocityJointInterface</hardwareInterface>  
    </joint>
    <actuator name="right_wheel_actuator">
      <mechanicalReduction>7</mechanicalReduction>
      <hardwareInterface>VelocityJointInterface</hardwareInterface>
    </actuator>
  </transmission>
  <link
    name="left_wheel">
    <inertial>
      <origin
        xyz="-4.7184E-16 -0.0125 4.7184E-16"
        rpy="0 0 0" />
      <mass
        value="0.1" />
      <inertia
        ixx="2.5621E-05"
        ixy="-3.0526E-18"
        ixz="-2.9995E-19"
        iyy="8.3419E-03"
        iyz="7.1293E-18"
        izz="2.5621E-05" />
    </inertial>
    <visual>
      <origin
        xyz="0 0 0"
        rpy="0 0 0" />
      <geometry>
        <mesh
          filename="package://ydpibot_description/meshes/left_wheel.STL" />
      </geometry>
      <material
        name="">
        <color
          rgba="0 1 1 1" />
      </material>
    </visual>
    <collision>
      <origin
        xyz="0 0 0"
        rpy="0 0 0" />
      <geometry>
        <mesh
          filename="package://ydpibot_description/meshes/left_wheel.STL" />
      </geometry>
    </collision>
  </link>
  <gazebo reference="left_wheel">
    <mu1 value="1.0"/>
    <mu2 value="1.0"/>
    <kp value="10000000.0"/>
    <kd value="10.0"/>
    <fdir1 value="1 0 0"/>
    <material>Gazebo/Yellow</material>
    <turnGravityOff>false</turnGravityOff>
  </gazebo>
  <joint
    name="left_wheel_joint"
    type="continuous">
    <origin
      xyz="-0.021967 0.08 0.0325"
      rpy="0 0 0" />
    <parent
      link="base_link" />
    <child
      link="left_wheel" />
    <axis
      xyz="0 1 0" />
  </joint>
  <transmission name="left_wheel_transmission">
    <type>transmission_interface/SimpleTransmission</type>
    <joint name="left_wheel_joint">
      <hardwareInterface>VelocityJointInterface</hardwareInterface>  
    </joint>
    <actuator name="left_wheel_actuator">
      <mechanicalReduction>7</mechanicalReduction>
      <hardwareInterface>VelocityJointInterface</hardwareInterface>
    </actuator>
  </transmission>
  <link
    name="caster_wheel_">
    <inertial>
      <origin
        xyz="-9.7039E-09 -9.3993E-09 0.0022919"
        rpy="0 0 0" />
      <mass
        value="0.4" />
      <inertia
        ixx="7.0984E-05"
        ixy="3.8139E-11"
        ixz="9.5484E-11"
        iyy="5.9612E-04"
        iyz="1.4958E-11"
        izz="8.4211E-05" />
    </inertial>
    <visual>
      <origin
        xyz="0 0 0"
        rpy="0 0 0" />
      <geometry>
        <mesh
          filename="package://ydpibot_description/meshes/caster_wheel_.STL" />
      </geometry>
      <material
        name="">
        <color
          rgba="1 0 1 1" />
      </material>
    </visual>
    <collision>
      <origin
        xyz="0 0 0"
        rpy="0 0 0" />
      <geometry>
        <mesh
          filename="package://ydpibot_description/meshes/caster_wheel_.STL" />
      </geometry>
    </collision>
  </link>  
  <gazebo reference="caster_wheel_">
    <mu1 value="0.0"/>
    <mu2 value="0.0"/>
    <kp value="10000000.0"/>
    <kd value="1.0"/>
    <fdir1 value="1 0 0"/>
    <material>Gazebo/White</material>
    <turnGravityOff>false</turnGravityOff>
  </gazebo>
  <joint
    name="caster_wheel__joint"
    type="fixed">
    <origin
      xyz="0.069075 0 0.033565"
      rpy="-3.1416 0 0" />
    <parent
      link="base_link" />
    <child
      link="caster_wheel_" />
    <axis
      xyz="0 0 0" />
  </joint>
  <link
    name="IMU">
    <inertial>
      <origin
        xyz="-0.021085 4.0683E-05 0.0050175"
        rpy="0 0 0" />
      <mass
        value="0.0014392" />
      <inertia
        ixx="3.8574E-08"
        ixy="2.8168E-14"
        ixz="-7.2192E-15"
        iyy="1.4941E-08"
        iyz="1.5273E-14"
        izz="4.2201E-08" />
    </inertial>
    <visual>
      <origin
        xyz="0 0 0"
        rpy="0 0 0" />
      <geometry>
        <mesh
          filename="package://ydpibot_description/meshes/IMU.STL" />
      </geometry>
      <material
        name="">
        <color
          rgba="0 0 1 1" />
      </material>
    </visual>
    <collision>
      <origin
        xyz="0 0 0"
        rpy="0 0 0" />
      <geometry>
        <mesh
          filename="package://ydpibot_description/meshes/IMU.STL" />
      </geometry>
    </collision>
  </link>
  <joint
    name="IMU_joint"
    type="fixed">
    <origin
      xyz="0.000205 0 0.04234"
      rpy="1.5708 0 0" />
    <parent
      link="base_link" />
    <child
      link="IMU" />
    <axis
      xyz="0 0 0" />
  </joint>
  <gazebo reference="IMU">
    <gravity>true</gravity>
    <material>Gazebo/Blue</material>
    <sensor name="imu_sensor" type="imu">
      <always_on>true</always_on>
      <update_rate>100</update_rate>
      <visualize>true</visualize>
      <topic>__default_topic__</topic>
      <plugin filename="libgazebo_ros_imu_sensor.so" name="imu_plugin">
        <topicName>imu</topicName>
        <bodyName>imu_link</bodyName>
        <updateRateHZ>10.0</updateRateHZ>
        <gaussianNoise>0.0</gaussianNoise>
        <xyzOffset>0 0 0</xyzOffset>
        <rpyOffset>0 0 0</rpyOffset>
        <frameName>imu_link</frameName>
        <initialOrientationAsReference>false</initialOrientationAsReference>
      </plugin>
      <pose>0 0 0 0 0 0</pose>
    </sensor>
  </gazebo>

  <gazebo>
    <plugin name="gazebo_ros_control" filename="libgazebo_ros_control.so">
      <robotNamespace>/</robotNamespace>
    </plugin>
  </gazebo>

</robot>