<?xml version="1.0" encoding="utf-8"?>
<!-- This URDF was automatically created by SolidWorks to URDF Exporter! Originally created by Stephen Brawner (brawner@gmail.com) 
     Commit Version: 1.6.0-4-g7f85cfe  Build Version: 1.6.7995.38578
     For more information, please see http://wiki.ros.org/sw_urdf_exporter -->
<robot
  name="ydpibot_description">
  <link
    name="base_link">
    <inertial>
      <origin
        xyz="0.093495 -0.17099 0.094111"
        rpy="0 0 0" />
      <mass
        value="0.11353" />
      <inertia
        ixx="0"
        ixy="0"
        ixz="0"
        iyy="0"
        iyz="0"
        izz="0" />
    </inertial>
    <visual>
      <origin
        xyz="0 0 0"
        rpy="0 0 0" />
      <geometry>
        <mesh
          filename="package://ydpibot_description/meshes/base_link.STL" />
      </geometry>
      <material
        name="">
        <color
          rgba="0.79216 0.81961 0.93333 1" />
      </material>
    </visual>
    <collision>
      <origin
        xyz="0 0 0"
        rpy="0 0 0" />
      <geometry>
        <mesh
          filename="package://ydpibot_description/meshes/base_link.STL" />
      </geometry>
    </collision>
  </link>
  <link
    name="Base_upper">
    <inertial>
      <origin
        xyz="-0.00023228 0.0015 2.7756E-17"
        rpy="0 0 0" />
      <mass
        value="0.072243" />
      <inertia
        ixx="7.9419E-05"
        ixy="7.2895E-21"
        ixz="2.2927E-19"
        iyy="0.00035752"
        iyz="-3.7269E-21"
        izz="0.00027821" />
    </inertial>
    <visual>
      <origin
        xyz="0 0 0"
        rpy="0 0 0" />
      <geometry>
        <mesh
          filename="package://ydpibot_description/meshes/Base_upper.STL" />
      </geometry>
      <material
        name="">
        <color
          rgba="0.79216 0.81961 0.93333 1" />
      </material>
    </visual>
    <collision>
      <origin
        xyz="0 0 0"
        rpy="0 0 0" />
      <geometry>
        <mesh
          filename="package://ydpibot_description/meshes/Base_upper.STL" />
      </geometry>
    </collision>
  </link>
  <joint
    name="Base_upper_joint"
    type="fixed">
    <origin
      xyz="0.10092 -0.17099 0.13642"
      rpy="1.5708 0 0" />
    <parent
      link="base_link" />
    <child
      link="Base_upper" />
    <axis
      xyz="0 0 0" />
  </joint>
  <link
    name="spacer1">
    <inertial>
      <origin
        xyz="8.3267E-17 -0.017 -2.7756E-17"
        rpy="0 0 0" />
      <mass
        value="0.0038202" />
      <inertia
        ixx="7.5881E-07"
        ixy="4.9502E-23"
        ixz="0"
        iyy="5.1484E-08"
        iyz="-2.6834E-23"
        izz="7.5881E-07" />
    </inertial>
    <visual>
      <origin
        xyz="0 0 0"
        rpy="0 0 0" />
      <geometry>
        <mesh
          filename="package://ydpibot_description/meshes/spacer1.STL" />
      </geometry>
      <material
        name="">
        <color
          rgba="0.79216 0.81961 0.93333 1" />
      </material>
    </visual>
    <collision>
      <origin
        xyz="0 0 0"
        rpy="0 0 0" />
      <geometry>
        <mesh
          filename="package://ydpibot_description/meshes/spacer1.STL" />
      </geometry>
    </collision>
  </link>
  <joint
    name="spacer1_joint"
    type="continuous">
    <origin
      xyz="0.084615 0 -0.055"
      rpy="0 0.33559 0" />
    <parent
      link="Base_upper" />
    <child
      link="spacer1" />
    <axis
      xyz="0 1 0" />
  </joint>
  <link
    name="spacer2">
    <inertial>
      <origin
        xyz="1.38777878078145E-16 -0.017 5.55111512312578E-17"
        rpy="0 0 0" />
      <mass
        value="0.00382017666676519" />
      <inertia
        ixx="7.58805628782363E-07"
        ixy="3.39136695613013E-23"
        ixz="0"
        iyy="5.14844204070296E-08"
        iyz="-2.25982421294763E-23"
        izz="7.58805628782363E-07" />
    </inertial>
    <visual>
      <origin
        xyz="0 0 0"
        rpy="0 0 0" />
      <geometry>
        <mesh
          filename="package://ydpibot_description/meshes/spacer2.STL" />
      </geometry>
      <material
        name="">
        <color
          rgba="0.792156862745098 0.819607843137255 0.933333333333333 1" />
      </material>
    </visual>
    <collision>
      <origin
        xyz="0 0 0"
        rpy="0 0 0" />
      <geometry>
        <mesh
          filename="package://ydpibot_description/meshes/spacer2.STL" />
      </geometry>
    </collision>
  </link>
  <joint
    name="spacer2_joint"
    type="continuous">
    <origin
      xyz="0.084615 0 0.055"
      rpy="0 0.33674 0" />
    <parent
      link="Base_upper" />
    <child
      link="spacer2" />
    <axis
      xyz="0 1 0" />
  </joint>
  <link
    name="spacer3">
    <inertial>
      <origin
        xyz="0 -0.017 0"
        rpy="0 0 0" />
      <mass
        value="0.00382017666676519" />
      <inertia
        ixx="7.58805628782362E-07"
        ixy="2.32527400477112E-23"
        ixz="0"
        iyy="5.14844204070295E-08"
        iyz="-1.73055673955825E-23"
        izz="7.58805628782362E-07" />
    </inertial>
    <visual>
      <origin
        xyz="0 0 0"
        rpy="0 0 0" />
      <geometry>
        <mesh
          filename="package://ydpibot_description/meshes/spacer3.STL" />
      </geometry>
      <material
        name="">
        <color
          rgba="0.792156862745098 0.819607843137255 0.933333333333333 1" />
      </material>
    </visual>
    <collision>
      <origin
        xyz="0 0 0"
        rpy="0 0 0" />
      <geometry>
        <mesh
          filename="package://ydpibot_description/meshes/spacer3.STL" />
      </geometry>
    </collision>
  </link>
  <joint
    name="spacer3_joint"
    type="continuous">
    <origin
      xyz="-0.084615 0 -0.055"
      rpy="0 0.33674 0" />
    <parent
      link="Base_upper" />
    <child
      link="spacer3" />
    <axis
      xyz="0 1 0" />
  </joint>
  <link
    name="spacer4">
    <inertial>
      <origin
        xyz="-2.42861286636753E-17 -0.017 2.77555756156289E-17"
        rpy="0 0 0" />
      <mass
        value="0.00382017666676519" />
      <inertia
        ixx="7.58805628782362E-07"
        ixy="1.43016865199273E-23"
        ixz="0"
        iyy="5.14844204070296E-08"
        iyz="3.29398282473415E-24"
        izz="7.58805628782362E-07" />
    </inertial>
    <visual>
      <origin
        xyz="0 0 0"
        rpy="0 0 0" />
      <geometry>
        <mesh
          filename="package://ydpibot_description/meshes/spacer4.STL" />
      </geometry>
      <material
        name="">
        <color
          rgba="0.792156862745098 0.819607843137255 0.933333333333333 1" />
      </material>
    </visual>
    <collision>
      <origin
        xyz="0 0 0"
        rpy="0 0 0" />
      <geometry>
        <mesh
          filename="package://ydpibot_description/meshes/spacer4.STL" />
      </geometry>
    </collision>
  </link>
  <joint
    name="spacer4_joint"
    type="continuous">
    <origin
      xyz="-0.084615 0 0.055"
      rpy="0 0.14715 0" />
    <parent
      link="Base_upper" />
    <child
      link="spacer4" />
    <axis
      xyz="0 1 0" />
  </joint>
  <link
    name="Lidar">
    <inertial>
      <origin
        xyz="-0.0100120175365926 -1.88737914186277E-15 -0.0157829888269581"
        rpy="0 0 0" />
      <mass
        value="0.0321236105023131" />
      <inertia
        ixx="6.04209032356703E-06"
        ixy="-8.51996030929602E-20"
        ixz="1.1886074166174E-21"
        iyy="1.77158746829917E-05"
        iyz="2.16870748621142E-21"
        izz="2.11948956350748E-05" />
    </inertial>
    <visual>
      <origin
        xyz="0 0 0"
        rpy="0 0 0" />
      <geometry>
        <mesh
          filename="package://ydpibot_description/meshes/Lidar.STL" />
      </geometry>
      <material
        name="">
        <color
          rgba="0.792156862745098 0.819607843137255 0.933333333333333 1" />
      </material>
    </visual>
    <collision>
      <origin
        xyz="0 0 0"
        rpy="0 0 0" />
      <geometry>
        <mesh
          filename="package://ydpibot_description/meshes/Lidar.STL" />
      </geometry>
    </collision>
  </link>
  <joint
    name="Lidar_joint"
    type="fixed">
    <origin
      xyz="-0.039725 0.04948 0"
      rpy="1.5708 0 -3.1416" />
    <parent
      link="Base_upper" />
    <child
      link="Lidar" />
    <axis
      xyz="0 0 0" />
  </joint>
  <link
    name="Wheel1">
    <inertial>
      <origin
        xyz="0 -1.38777878078145E-17 0.0125"
        rpy="0 0 0" />
      <mass
        value="0.075103699374881" />
      <inertia
        ixx="2.56213141096599E-05"
        ixy="-2.99951956532367E-39"
        ixz="-4.41162993361618E-23"
        iyy="2.56213141096599E-05"
        iyz="-7.12930731372928E-38"
        izz="4.34193262011031E-05" />
    </inertial>
    <visual>
      <origin
        xyz="0 0 0"
        rpy="0 0 0" />
      <geometry>
        <mesh
          filename="package://ydpibot_description/meshes/Wheel1.STL" />
      </geometry>
      <material
        name="">
        <color
          rgba="0.792156862745098 0.819607843137255 0.933333333333333 1" />
      </material>
    </visual>
    <collision>
      <origin
        xyz="0 0 0"
        rpy="0 0 0" />
      <geometry>
        <mesh
          filename="package://ydpibot_description/meshes/Wheel1.STL" />
      </geometry>
    </collision>
  </link>
  <joint
    name="Wheel1_joint"
    type="continuous">
    <origin
      xyz="0.080916 -0.090994 0.079422"
      rpy="1.5708 0 0" />
    <parent
      link="base_link" />
    <child
      link="Wheel1" />
    <axis
      xyz="0 0 1" />
  </joint>
  <link
    name="Wheel2">
    <inertial>
      <origin
        xyz="0 0 0.0125"
        rpy="0 0 0" />
      <mass
        value="0.075104" />
      <inertia
        ixx="2.5621E-05"
        ixy="-2.9995E-39"
        ixz="-5.4594E-37"
        iyy="2.5621E-05"
        iyz="-7.1293E-38"
        izz="4.3419E-05" />
    </inertial>
    <visual>
      <origin
        xyz="0 0 0"
        rpy="0 0 0" />
      <geometry>
        <mesh
          filename="package://ydpibot_description/meshes/Wheel2.STL" />
      </geometry>
      <material
        name="">
        <color
          rgba="0.79216 0.81961 0.93333 1" />
      </material>
    </visual>
    <collision>
      <origin
        xyz="0 0 0"
        rpy="0 0 0" />
      <geometry>
        <mesh
          filename="package://ydpibot_description/meshes/Wheel2.STL" />
      </geometry>
    </collision>
  </link>
  <joint
    name="Wheel2_joint"
    type="continuous">
    <origin
      xyz="0.080916 -0.22599 0.079422"
      rpy="1.5708 0 0" />
    <parent
      link="base_link" />
    <child
      link="Wheel2" />
    <axis
      xyz="0 0 1" />
  </joint>
  <link
    name="Caster Wheel Base">
    <inertial>
      <origin
        xyz="0.017052 0.003709 -0.0125"
        rpy="0 0 0" />
      <mass
        value="0.044833" />
      <inertia
        ixx="4.8267E-06"
        ixy="-1.3671E-23"
        ixz="-5.1509E-22"
        iyy="9.3882E-06"
        iyz="-4.8576E-22"
        izz="4.8267E-06" />
    </inertial>
    <visual>
      <origin
        xyz="0 0 0"
        rpy="0 0 0" />
      <geometry>
        <mesh
          filename="package://ydpibot_description/meshes/Caster Wheel Base.STL" />
      </geometry>
      <material
        name="">
        <color
          rgba="0.52941 0.54902 0.54902 1" />
      </material>
    </visual>
    <collision>
      <origin
        xyz="0 0 0"
        rpy="0 0 0" />
      <geometry>
        <mesh
          filename="package://ydpibot_description/meshes/Caster Wheel Base.STL" />
      </geometry>
    </collision>
  </link>
  <joint
    name="Caster Wheel Base_joint"
    type="fixed">
    <origin
      xyz="0.15791 -0.18349 0.093422"
      rpy="1.5708 0 0" />
    <parent
      link="base_link" />
    <child
      link="Caster Wheel Base" />
    <axis
      xyz="0 0 0" />
  </joint>
  <link
    name="Caster Wheel cage">
    <inertial>
      <origin
        xyz="0.019414 -0.0053453 -0.0125"
        rpy="0 0 0" />
      <mass
        value="0.056621" />
      <inertia
        ixx="7.5423E-06"
        ixy="8.202E-07"
        ixz="9.6169E-12"
        iyy="1.077E-05"
        iyz="-4.6142E-11"
        izz="8.0977E-06" />
    </inertial>
    <visual>
      <origin
        xyz="0 0 0"
        rpy="0 0 0" />
      <geometry>
        <mesh
          filename="package://ydpibot_description/meshes/Caster Wheel cage.STL" />
      </geometry>
      <material
        name="">
        <color
          rgba="0.52941 0.54902 0.54902 1" />
      </material>
    </visual>
    <collision>
      <origin
        xyz="0 0 0"
        rpy="0 0 0" />
      <geometry>
        <mesh
          filename="package://ydpibot_description/meshes/Caster Wheel cage.STL" />
      </geometry>
    </collision>
  </link>
  <joint
    name="Caster Wheel cage_joint"
    type="fixed">
    <origin
      xyz="0.0037189 -0.004 0.0039088"
      rpy="0 0.25588 0" />
    <parent
      link="Caster Wheel Base" />
    <child
      link="Caster Wheel cage" />
    <axis
      xyz="0 0 0" />
  </joint>
  <link
    name="Caster Wheel">
    <inertial>
      <origin
        xyz="0 0 0"
        rpy="0 0 0" />
      <mass
        value="0.017472" />
      <inertia
        ixx="2.2415E-06"
        ixy="1.0257E-22"
        ixz="-6.0219E-22"
        iyy="2.2415E-06"
        iyz="-1.5882E-21"
        izz="3.5831E-06" />
    </inertial>
    <visual>
      <origin
        xyz="0 0 0"
        rpy="0 0 0" />
      <geometry>
        <mesh
          filename="package://ydpibot_description/meshes/Caster Wheel.STL" />
      </geometry>
      <material
        name="">
        <color
          rgba="0.25098 0.25098 0.25098 1" />
      </material>
    </visual>
    <collision>
      <origin
        xyz="0 0 0"
        rpy="0 0 0" />
      <geometry>
        <mesh
          filename="package://ydpibot_description/meshes/Caster Wheel.STL" />
      </geometry>
    </collision>
  </link>
  <joint
    name="Caster Wheel_joint"
    type="fixed">
    <origin
      xyz="0.033052 -0.023 -0.0125"
      rpy="0 0 1.7635" />
    <parent
      link="Caster Wheel cage" />
    <child
      link="Caster Wheel" />
    <axis
      xyz="0 0 0" />
  </joint>
  <link
    name="Lower_Base">
    <inertial>
      <origin
        xyz="-0.007421 -0.0053109 2.7756E-17"
        rpy="0 0 0" />
      <mass
        value="0.11353" />
      <inertia
        ixx="0.0002007"
        ixy="-9.7266E-06"
        ixz="4.5268E-19"
        iyy="0.00047883"
        iyz="-8.8669E-22"
        izz="0.00030078" />
    </inertial>
    <visual>
      <origin
        xyz="0 0 0"
        rpy="0 0 0" />
      <geometry>
        <mesh
          filename="package://ydpibot_description/meshes/Lower_Base.STL" />
      </geometry>
      <material
        name="">
        <color
          rgba="0.79216 0.81961 0.93333 1" />
      </material>
    </visual>
    <collision>
      <origin
        xyz="0 0 0"
        rpy="0 0 0" />
      <geometry>
        <mesh
          filename="package://ydpibot_description/meshes/Lower_Base.STL" />
      </geometry>
    </collision>
  </link>
  <joint
    name="Lower_Base_joint"
    type="fixed">
    <origin
      xyz="0.10092 -0.17099 0.099422"
      rpy="1.5708 0 0" />
    <parent
      link="base_link" />
    <child
      link="Lower_Base" />
    <axis
      xyz="0 0 0" />
  </joint>
</robot>